Logging started at 18:18:50 on 14 Mar 2013
QIIME version: 1.6.0

No qiime config provided.
No params provided.

Creating output subdirectory '/home/nbokulic/open_reference_otus/S16S-1/multiple_assign_taxonomy/S16S-1' if it doesn't already exist.
Executing commands.

# Assigning taxonomy (Mothur, confidence: 0.6) command 
assign_taxonomy.py -i /home/nbokulic/open_reference_otus/S16S-1/rep_set.fna -o /home/nbokulic/open_reference_otus/S16S-1/multiple_assign_taxonomy/S16S-1/mothur_0.6.tmp -c 0.6 -m mothur -r /home/nbokulic/gg_12_10/rep_set/gg_97_otus_6oct2010.fasta -t /home/nbokulic/gg_12_10/gg_12_10_taxonomy.txt



*** ERROR RAISED DURING STEP: Assigning taxonomy (Mothur, confidence: 0.6)
Command run was:
 assign_taxonomy.py -i /home/nbokulic/open_reference_otus/S16S-1/rep_set.fna -o /home/nbokulic/open_reference_otus/S16S-1/multiple_assign_taxonomy/S16S-1/mothur_0.6.tmp -c 0.6 -m mothur -r /home/nbokulic/gg_12_10/rep_set/gg_97_otus_6oct2010.fasta -t /home/nbokulic/gg_12_10/gg_12_10_taxonomy.txt
Command returned exit status: 1
Stdout:

Stderr
Traceback (most recent call last):
  File "/share/apps/qiime-1.6.0/scripts/assign_taxonomy.py", line 305, in <module>
    main()
  File "/share/apps/qiime-1.6.0/scripts/assign_taxonomy.py", line 283, in main
    result_path=temp_result_path,log_path=log_path)
  File "/share/apps/qiime-1.6.0/lib/qiime/assign_taxonomy.py", line 367, in __call__
    output_fp=result_path,
  File "/share/apps/qiime-1.6.0/lib/qiime/pycogent_backports/mothur.py", line 508, in mothur_classify_file
    assignments = list(parse_mothur_assignments(result['assignments']))
KeyError: 'assignments'


Logging stopped at 18:19:29 on 14 Mar 2013
